<?xml version="1.0" encoding="utf-8"?>
<robot name="T5-03">
  <link name="base"/>
  <joint name="world_to_arm_base" type="fixed">
    <parent link="base"/>
    <child link="link_car"/>
    <origin rpy="0 0 0" xyz="0 0 0.6"/>
  </joint>
  <link name="link_car">
    <visual>
      <origin xyz="0 0 0" rpy="0 0 0" />
      <geometry>
        <mesh filename="package://ocs2_robotic_assets/resources/mobile_manipulator/t5/meshes/base_car.stl" />
      </geometry>
    </visual>
    <collision>
      <origin xyz="0 0 0" rpy="0 0 0" />
      <geometry>
        <mesh filename="package://ocs2_robotic_assets/resources/mobile_manipulator/t5/meshes/base_car.stl" />
      </geometry>
    </collision>
  </link>
  <joint name="joint_lift" type="fixed">
    <parent link="link_car"/>
    <child link="link_base"/>
    <origin rpy="0 0 0" xyz="0 0 0"/>
    <axis xyz="0 0 1"/>
    <limit effort="1.0" lower="0" upper="1.0" velocity="0.1"/>
  </joint>
  <link name="link_base">
    <visual>
      <geometry>
        <mesh filename="package://ocs2_robotic_assets/resources/mobile_manipulator/t5/meshes/base.stl"/>
      </geometry>
      <origin rpy="0 0 0" xyz="0 0 0"/>
    </visual>
    <collision>
      <geometry>
        <mesh filename="package://ocs2_robotic_assets/resources/mobile_manipulator/t5/meshes/base.stl"/>
      </geometry>
      <origin rpy="0 0 0" xyz="0 0 0"/>
    </collision>
  </link>
  <joint name="joint1" type="revolute">
    <parent link="link_base"/>
    <child link="link1"/>
    <origin rpy="0 0 0" xyz="0 0 0.267"/>
    <axis xyz="0 0 1"/>
    <limit effort="50.0" lower="-6.28" upper="6.28" velocity="3.14"/>
  </joint>
  <link name="link1">
    <visual>
      <geometry>
        <mesh filename="package://ocs2_robotic_assets/resources/mobile_manipulator/t5/meshes/link1.stl"/>
      </geometry>
      <origin rpy="0 0 0" xyz="0 0 0"/>
    </visual>
    <collision>
      <geometry>
        <mesh filename="package://ocs2_robotic_assets/resources/mobile_manipulator/t5/meshes/link1.stl"/>
      </geometry>
      <origin rpy="0 0 0" xyz="0 0 0"/>
    </collision>
  </link>
  <joint name="joint2" type="revolute">
    <parent link="link1"/>
    <child link="link2"/>
    <origin rpy="-1.5708 0 0" xyz="0 0 0"/>
    <axis xyz="0 0 1"/>
    <limit effort="50.0" lower="-2.0" upper="2.0" velocity="3.14"/>
  </joint>
  <link name="link2">
    <visual>
      <geometry>
        <mesh filename="package://ocs2_robotic_assets/resources/mobile_manipulator/t5/meshes/link2.stl"/>
      </geometry>
      <origin rpy="0 0 0" xyz="0 0 0"/>
    </visual>
    <collision>
      <geometry>
        <mesh filename="package://ocs2_robotic_assets/resources/mobile_manipulator/t5/meshes/link2.stl"/>
      </geometry>
      <origin rpy="0 0 0" xyz="0 0 0"/>
    </collision>
  </link>
  <joint name="joint3" type="revolute">
    <parent link="link2"/>
    <child link="link3"/>
    <origin rpy="0 0 0" xyz="0.0535 -0.2845 0"/>
    <axis xyz="0 0 1"/>
    <limit effort="32.0" lower="-3.8" upper="0.185" velocity="3.14"/>
  </joint>
  <link name="link3">
    <visual>
      <geometry>
        <mesh filename="package://ocs2_robotic_assets/resources/mobile_manipulator/t5/meshes/link3.stl"/>
      </geometry>
      <origin rpy="0 0 0" xyz="0 0 0"/>
    </visual>
    <collision>
      <geometry>
        <mesh filename="package://ocs2_robotic_assets/resources/mobile_manipulator/t5/meshes/link3.stl"/>
      </geometry>
      <origin rpy="0 0 0" xyz="0 0 0"/>
    </collision>
  </link>
  <joint name="joint4" type="revolute">
    <parent link="link3"/>
    <child link="link4"/>
    <origin rpy="-1.5708 0 0" xyz="0.0775 0.3425 0"/>
    <axis xyz="0 0 1"/>
    <!-- <limit effort="32.0" lower="-6.28" upper="6.28" velocity="3.14"/> -->
    <limit effort="32.0" lower="-3.14" upper="3.14" velocity="3.14"/>
  </joint>
  <link name="link4">
    <visual>
      <geometry>
        <mesh filename="package://ocs2_robotic_assets/resources/mobile_manipulator/t5/meshes/link4.stl"/>
      </geometry>
      <origin rpy="0 0 0" xyz="0 0 0"/>
    </visual>
    <collision>
      <geometry>
        <mesh filename="package://ocs2_robotic_assets/resources/mobile_manipulator/t5/meshes/link4.stl"/>
      </geometry>
      <origin rpy="0 0 0" xyz="0 0 0"/>
    </collision>
  </link>
  <joint name="joint5" type="revolute">
    <parent link="link4"/>
    <child link="link5"/>
    <origin rpy="1.5708 0 0" xyz="0 0 0"/>
    <axis xyz="0 0 1"/>
    <limit effort="32.0" lower="-1.5" upper="3.04" velocity="3.14"/>
  </joint>
  <link name="link5">
    <visual>
      <geometry>
        <mesh filename="package://ocs2_robotic_assets/resources/mobile_manipulator/t5/meshes/link5.stl"/>
      </geometry>
      <origin rpy="0 0 0" xyz="0 0 0"/>
    </visual>
    <collision>
      <geometry>
        <mesh filename="package://ocs2_robotic_assets/resources/mobile_manipulator/t5/meshes/link5.stl"/>
      </geometry>
      <origin rpy="0 0 0" xyz="0 0 0"/>
    </collision>
  </link>
  <joint name="joint6" type="revolute">
    <parent link="link5"/>
    <child link="link6"/>
    <origin rpy="-1.5708 0 0" xyz="0.076 0.097 0"/>
    <axis xyz="0 0 1"/>
    <!-- <limit effort="20.0" lower="-6.28" upper="6.28" velocity="3.14"/> -->
    <limit effort="20.0" lower="-3.14" upper="3.14" velocity="3.14"/>
  </joint>
  <link name="link6">
    <visual>
      <geometry>
        <mesh filename="package://ocs2_robotic_assets/resources/mobile_manipulator/t5/meshes/link6_full.stl"/>
        <!-- <mesh filename="meshes/link6_full_test.stl"/> -->
      </geometry>
      <origin rpy="0 0 0" xyz="0 0 0"/>
    </visual>
    <collision>
      <geometry>
        <mesh filename="package://ocs2_robotic_assets/resources/mobile_manipulator/t5/meshes/link6_full.stl"/>
        <!-- <mesh filename="meshes/link6_full_test.stl"/> -->
      </geometry>
      <origin rpy="0 0 0" xyz="0 0 0"/>
    </collision>
  </link>
  <joint name="joint_eef" type="fixed">
    <origin rpy="0 0 0" xyz="0 0 0.39"/>
    <parent link="link6"/>
    <child link="link_eef"/>
  </joint>
  <link name="link_eef"/>
</robot>
