<?xml version="1.0"?>
<robot name="dual_link_manipulator">

  <link name="world"/>

  <joint name="world_to_base" type="fixed">
    <parent link="world"/>
    <child link="base"/>
    <origin rpy="0 0 0" xyz="0.0 0.0 0.0"/>
    <axis xyz="1 0 0"/>
  </joint>

  <link name="base">
    <visual>
      <geometry>
        <cylinder radius="0.05" length="0.06"/>
      </geometry>
      <origin rpy="0 1.5707963267948966 0" xyz="0 0 0.0"/>
      <material name="grey">
        <color rgba="0.75 0.75 0.75 0.8"/>
      </material>
    </visual>
    <inertial>
      <mass value="0.0"/>
      <inertia ixx="0.0" ixy="0.0" ixz="0.0" iyy="0.0" iyz="0.0" izz="0.0"/>
    </inertial>
  </link>

  <joint name="joint_1" type="revolute">
    <axis xyz="1 0 0"/>
    <origin xyz="0.0 0.0 0.0" rpy="-1.5707963267948966 0.0 0.0"/>
    <parent link="base"/>
    <child link="link_1"/>
    <limit effort="100000.0" lower="-15" upper="15" velocity="50"/>
    <dynamics damping="0.0" friction="0.0"/>
  </joint>

  <link name="link_1">
    <visual>
      <geometry>
        <box size="0.05 0.05 1.0"/>
      </geometry>
      <origin rpy="0 0 0" xyz="0 0 0.5"/>
      <material name="Blue">
      <color rgba="0.5 0.7 1.0 1.0"/>      
      </material>
    </visual>
    <collision>
      <geometry>
          <box size="0.5 0.5 1.0"/>
      </geometry>
      <origin xyz="0 0 0"/>
    </collision>
    <inertial>
      <mass value="2.0"/>
      <inertia ixx="0.167083" ixy="0.0" ixz="0.0" iyy="0.167083" iyz="0.0" izz="0.00083"/>
    </inertial>
  </link>

  <joint name="joint_2" type="revolute">
    <axis xyz="1 0 0"/>
    <origin xyz="0.0 0.0 1.0" rpy="0.0 0.0 0.0"/>
    <parent link="link_1"/>
    <child link="link_2"/>
    <limit effort="100000.0" lower="-15" upper="15" velocity="50"/>
    <dynamics damping="0.0" friction="0.0"/>
  </joint>

  <link name="link_2">
    <visual>
      <geometry>
        <box size="0.05 0.05 1.0"/>
      </geometry>
      <origin rpy="0 0 0" xyz="0 0 0.5"/>
      <material name="Orange">
        <color rgba="1.0 0.423529411765 0.0392156862745 1.0"/>
      </material>
    </visual>
    <inertial>
      <origin rpy="0 0 0" xyz="0 0 0.5"/>
      <mass value="1.0"/>
      <inertia ixx="0.08354" ixy="0.0" ixz="0.08354" iyy="0.0" iyz="0.0" izz="0.000415"/>
    </inertial>
     <collision>
      <geometry>
        <box size="0.05 0.05 1.0"/>
      </geometry>
      <origin rpy="0 0 0" xyz="0 0 0.5"/>
    </collision>
  </link>

</robot>
